<?xml version="1.0" ?>
<!-- =================================================================================== -->
<!-- |    This document was autogenerated by xacro from abb_irb4600_60_205.xacro       | -->
<!-- |    EDITING THIS FILE BY HAND IS NOT RECOMMENDED                                 | -->
<!-- =================================================================================== -->
<robot name="abb_irb4600_60_205" xmlns:xacro="http://ros.org/wiki/xacro">
  <gazebo>
    <plugin filename="libgazebo_ros_control.so" name="gazebo_ros_control">
      <robotNamespace>/abb_irb_4600</robotNamespace>
      <robotSimType>gazebo_ros_control/DefaultRobotHWSim</robotSimType>
    </plugin>
  </gazebo>
  <!-- Link1 -->
  <gazebo reference="base_link">
    <material>Gazebo/Orange</material>
  </gazebo>
  <gazebo reference="link_1">
    <material>Gazebo/Orange</material>
  </gazebo>
  <gazebo reference="link_2">
    <material>Gazebo/Orange</material>
  </gazebo>
  <gazebo reference="link_3">
    <material>Gazebo/Orange</material>
  </gazebo>
  <gazebo reference="link_4">
    <material>Gazebo/Orange</material>
  </gazebo>
  <gazebo reference="link_5">
    <material>Gazebo/Orange</material>
  </gazebo>
  <gazebo reference="link_6">
    <material>Gazebo/Orange</material>
  </gazebo>
  <gazebo reference="tool0">
    <material>Gazebo/Orange</material>
  </gazebo>
  <!-- link list -->
  <link name="base_link">
    <visual>
      <origin rpy="0 0 0" xyz="0 0 0"/>
      <geometry>
        <mesh filename="package://abb_camera_simulation/meshes/abb_irb4600_60_205/visual/base_link.stl"/>
      </geometry>
      <material name="abb_white">
        <color rgba="0.8 0.8 0.8 1"/>
      </material>
    </visual>
    <collision>
      <origin rpy="0 0 0" xyz="0 0 0"/>
      <geometry>
        <mesh filename="package://abb_camera_simulation/meshes/abb_irb4600_60_205/collision/base_link.stl"/>
      </geometry>
      <material name="yellow">
        <color rgba="0 1 1 1"/>
      </material>
    </collision>
  </link>
  <link name="link_1">
    <visual>
      <origin rpy="0 0 0" xyz="0 0 0"/>
      <geometry>
        <mesh filename="package://abb_camera_simulation/meshes/abb_irb4600_60_205/visual/link_1.stl"/>
      </geometry>
      <material name="abb_white"/>
    </visual>
    <collision>
      <origin rpy="0 0 0" xyz="0 0 0"/>
      <geometry>
        <mesh filename="package://abb_camera_simulation/meshes/abb_irb4600_60_205/collision/link_1.stl"/>
      </geometry>
      <material name="yellow"/>
    </collision>
  </link>
  <link name="link_2">
    <visual>
      <origin rpy="0 0 0" xyz="0 0 0"/>
      <geometry>
        <mesh filename="package://abb_camera_simulation/meshes/abb_irb4600_60_205/visual/link_2.stl"/>
      </geometry>
      <material name="abb_white"/>
    </visual>
    <collision>
      <origin rpy="0 0 0" xyz="0 0 0"/>
      <geometry>
        <mesh filename="package://abb_camera_simulation/meshes/abb_irb4600_60_205/collision/link_2.stl"/>
      </geometry>
      <material name="yellow"/>
    </collision>
  </link>
  <link name="link_3">
    <visual>
      <origin rpy="0 0 0" xyz="0 0 0"/>
      <geometry>
        <mesh filename="package://abb_camera_simulation/meshes/abb_irb4600_60_205/visual/link_3.stl"/>
      </geometry>
      <material name="abb_white"/>
    </visual>
    <collision>
      <origin rpy="0 0 0" xyz="0 0 0"/>
      <geometry>
        <mesh filename="package://abb_camera_simulation/meshes/abb_irb4600_60_205/collision/link_3.stl"/>
      </geometry>
      <material name="yellow"/>
    </collision>
  </link>
  <link name="link_4">
    <visual>
      <origin rpy="0 0 0" xyz="0 0 0"/>
      <geometry>
        <mesh filename="package://abb_camera_simulation/meshes/abb_irb4600_60_205/visual/link_4.stl"/>
      </geometry>
      <material name="abb_white"/>
    </visual>
    <collision>
      <origin rpy="0 0 0" xyz="0 0 0"/>
      <geometry>
        <mesh filename="package://abb_camera_simulation/meshes/abb_irb4600_60_205/collision/link_4.stl"/>
      </geometry>
      <material name="yellow"/>
    </collision>
  </link>
  <link name="link_5">
    <visual>
      <origin rpy="0 0 0" xyz="0 0 0"/>
      <geometry>
        <mesh filename="package://abb_camera_simulation/meshes/abb_irb4600_60_205/visual/link_5.stl"/>
      </geometry>
      <material name="abb_white"/>
    </visual>
    <collision>
      <origin rpy="0 0 0" xyz="0 0 0"/>
      <geometry>
        <mesh filename="package://abb_camera_simulation/meshes/abb_irb4600_60_205/collision/link_5.stl"/>
      </geometry>
      <material name="yellow"/>
    </collision>
  </link>
  <link name="link_6">
    <visual>
      <origin rpy="0 0 0" xyz="0 0 0"/>
      <geometry>
        <mesh filename="package://abb_camera_simulation/meshes/abb_irb4600_60_205/visual/link_6.stl"/>
      </geometry>
      <material name="abb_grey">
        <color rgba="0.2 0.2 0.2 1"/>
      </material>
    </visual>
    <collision>
      <origin rpy="0 0 0" xyz="0 0 0"/>
      <geometry>
        <mesh filename="package://abb_camera_simulation/meshes/abb_irb4600_60_205/collision/link_6.stl"/>
      </geometry>
      <material name="yellow"/>
    </collision>
  </link>
  <link name="tool0" >
  <!--<link name= "kinect">-->
    <visual>
      <!-- <origin rpy="-1.57 0 1.57" xyz="-0.025 0 -0.125"/>-->
      <origin rpy="0 0 1.57" xyz="0 0 0.02"/>
      <geometry>
        <mesh filename="package://abb_camera_simulation/meshes/kinect/visual/kinect_sensor.stl" scale="0.001 0.001 0.001"/>
      </geometry>
      <material name="abb_grey">
        <color rgba="0.2 0.2 0.2 1"/>
      </material>
    </visual>
    <collision>
      <!--<origin rpy="-1.57 0 1.57" xyz="-0.025 0 -0.125"/>-->
       <origin rpy="0 0 1.57" xyz="0 0 0.02"/>
      <geometry>
        <mesh filename="package://abb_camera_simulation/meshes/kinect/collision/kinect_sensor.stl" scale="0.001 0.001 0.001"/>
      </geometry>
      <material name="yellow"/>
    </collision>
  </link>
  <!-- end of link list -->
  <!-- TODO ALL JOINT LIMITS limits are edited and reduced to lower values-->
  <!-- joint list -->
  <joint name="joint_1" type="revolute">
    <origin rpy="1.10409999285604E-14 0 0" xyz="0 0 0.1535"/>
    <parent link="base_link"/>
    <child link="link_1"/>
    <axis xyz="0 0 1"/>
    <limit effort="0" lower="-2.62" upper="2.62" velocity="3.05"/>
  </joint>
  <joint name="joint_2" type="revolute">
    <origin rpy="-1.57772181044202E-30 0 0" xyz="0.174999999999998 -0.0515489073390827 0.341500000000001"/>
    <parent link="link_1"/>
    <child link="link_2"/>
    <axis xyz="0 1 0"/>
    <limit effort="0" lower="-1.57" upper="1.57" velocity="3.05"/>
  </joint>
  <joint name="joint_3" type="revolute">
    <origin rpy="-1.11022302462516E-14 0 0" xyz="0 0 0.9"/>
    <parent link="link_2"/>
    <child link="link_3"/>
    <axis xyz="0 1 0"/>
    <limit effort="0" lower="-3.14" upper="1.31" velocity="4.36"/>
  </joint>
  <joint name="joint_4" type="revolute">
    <origin rpy="0 0 0" xyz="0.331499999999985 0.0515489073390958 0.175000000000008"/>
    <parent link="link_3"/>
    <child link="link_4"/>
    <axis xyz="1 0 0"/>
    <limit effort="0" lower="-6.98" upper="6.98" velocity="4.36"/>
  </joint>
  <joint name="joint_5" type="revolute">
    <origin rpy="0 0 0" xyz="0.628499999999995 0 0"/>
    <parent link="link_4"/>
    <child link="link_5"/>
    <axis xyz="0 1 0"/>
    <limit effort="0" lower="-2.09" upper="2.18" velocity="4.36"/>
  </joint>
  <joint name="joint_6" type="revolute">
    <origin rpy="0 0 0" xyz="0 0 0"/>
    <parent link="link_5"/>
    <child link="link_6"/>
    <axis xyz="1 0 0"/>
    <limit effort="0" lower="-6.98" upper="6.98" velocity="6.28"/>
  </joint>
  <joint name="joint_6-tool0" type="fixed">
    <parent link="link_6"/>
    <child link="tool0"/>
    <origin rpy="0 1.570796 0" xyz="0.135 0 0"/>
  </joint>
  <!--<joint name="tool0-kinect" type="fixed">
    <parent link="tool0"/>
    <child link="kinect"/>
    <origin rpy="0 1.570796 0" xyz="0.135 0 0"/>
  </joint>-->
</robot>
